[2023-02-25T00:02:41.374+0000] {taskinstance.py:1083} INFO - Dependencies all met for <TaskInstance: cms_asp_noc.download_file scheduled__2023-02-24T00:00:00+00:00 [queued]>
[2023-02-25T00:02:41.391+0000] {taskinstance.py:1083} INFO - Dependencies all met for <TaskInstance: cms_asp_noc.download_file scheduled__2023-02-24T00:00:00+00:00 [queued]>
[2023-02-25T00:02:41.392+0000] {taskinstance.py:1279} INFO - 
--------------------------------------------------------------------------------
[2023-02-25T00:02:41.392+0000] {taskinstance.py:1280} INFO - Starting attempt 1 of 1
[2023-02-25T00:02:41.393+0000] {taskinstance.py:1281} INFO - 
--------------------------------------------------------------------------------
[2023-02-25T00:02:41.406+0000] {taskinstance.py:1300} INFO - Executing <Task(PythonOperator): download_file> on 2023-02-24 00:00:00+00:00
[2023-02-25T00:02:41.427+0000] {standard_task_runner.py:55} INFO - Started process 7536 to run task
[2023-02-25T00:02:41.442+0000] {standard_task_runner.py:82} INFO - Running: ['***', 'tasks', 'run', 'cms_asp_noc', 'download_file', 'scheduled__2023-02-24T00:00:00+00:00', '--job-id', '1854', '--raw', '--subdir', 'DAGS_FOLDER/cms_upd.py', '--cfg-path', '/tmp/tmpjv3q4ea8']
[2023-02-25T00:02:41.459+0000] {standard_task_runner.py:83} INFO - Job 1854: Subtask download_file
[2023-02-25T00:02:42.566+0000] {task_command.py:388} INFO - Running <TaskInstance: cms_asp_noc.download_file scheduled__2023-02-24T00:00:00+00:00 [running]> on host 2886274f27ea
[2023-02-25T00:02:42.661+0000] {taskinstance.py:1509} INFO - Exporting the following env vars:
AIRFLOW_CTX_DAG_OWNER=***
AIRFLOW_CTX_DAG_ID=cms_asp_noc
AIRFLOW_CTX_TASK_ID=download_file
AIRFLOW_CTX_EXECUTION_DATE=2023-02-24T00:00:00+00:00
AIRFLOW_CTX_TRY_NUMBER=1
AIRFLOW_CTX_DAG_RUN_ID=scheduled__2023-02-24T00:00:00+00:00
[2023-02-25T00:36:12.951+0000] {taskinstance.py:1768} ERROR - Task failed with exception
Traceback (most recent call last):
  File "/home/airflow/.local/lib/python3.7/site-packages/urllib3/connectionpool.py", line 710, in urlopen
    chunked=chunked,
  File "/home/airflow/.local/lib/python3.7/site-packages/urllib3/connectionpool.py", line 449, in _make_request
    six.raise_from(e, None)
  File "<string>", line 3, in raise_from
  File "/home/airflow/.local/lib/python3.7/site-packages/urllib3/connectionpool.py", line 444, in _make_request
    httplib_response = conn.getresponse()
  File "/usr/local/lib/python3.7/http/client.py", line 1373, in getresponse
    response.begin()
  File "/usr/local/lib/python3.7/http/client.py", line 319, in begin
    version, status, reason = self._read_status()
  File "/usr/local/lib/python3.7/http/client.py", line 288, in _read_status
    raise RemoteDisconnected("Remote end closed connection without"
http.client.RemoteDisconnected: Remote end closed connection without response

During handling of the above exception, another exception occurred:

Traceback (most recent call last):
  File "/home/airflow/.local/lib/python3.7/site-packages/requests/adapters.py", line 499, in send
    timeout=timeout,
  File "/home/airflow/.local/lib/python3.7/site-packages/urllib3/connectionpool.py", line 788, in urlopen
    method, url, error=e, _pool=self, _stacktrace=sys.exc_info()[2]
  File "/home/airflow/.local/lib/python3.7/site-packages/urllib3/util/retry.py", line 550, in increment
    raise six.reraise(type(error), error, _stacktrace)
  File "/home/airflow/.local/lib/python3.7/site-packages/urllib3/packages/six.py", line 769, in reraise
    raise value.with_traceback(tb)
  File "/home/airflow/.local/lib/python3.7/site-packages/urllib3/connectionpool.py", line 710, in urlopen
    chunked=chunked,
  File "/home/airflow/.local/lib/python3.7/site-packages/urllib3/connectionpool.py", line 449, in _make_request
    six.raise_from(e, None)
  File "<string>", line 3, in raise_from
  File "/home/airflow/.local/lib/python3.7/site-packages/urllib3/connectionpool.py", line 444, in _make_request
    httplib_response = conn.getresponse()
  File "/usr/local/lib/python3.7/http/client.py", line 1373, in getresponse
    response.begin()
  File "/usr/local/lib/python3.7/http/client.py", line 319, in begin
    version, status, reason = self._read_status()
  File "/usr/local/lib/python3.7/http/client.py", line 288, in _read_status
    raise RemoteDisconnected("Remote end closed connection without"
urllib3.exceptions.ProtocolError: ('Connection aborted.', RemoteDisconnected('Remote end closed connection without response'))

During handling of the above exception, another exception occurred:

Traceback (most recent call last):
  File "/home/airflow/.local/lib/python3.7/site-packages/airflow/operators/python.py", line 175, in execute
    return_value = self.execute_callable()
  File "/home/airflow/.local/lib/python3.7/site-packages/airflow/operators/python.py", line 192, in execute_callable
    return self.python_callable(*self.op_args, **self.op_kwargs)
  File "/opt/airflow/dags/cms_pg/download_new_files.py", line 29, in download_zip_files
    reqs = requests.get(web_urls.format(year))
  File "/home/airflow/.local/lib/python3.7/site-packages/requests/api.py", line 73, in get
    return request("get", url, params=params, **kwargs)
  File "/home/airflow/.local/lib/python3.7/site-packages/requests/api.py", line 59, in request
    return session.request(method=method, url=url, **kwargs)
  File "/home/airflow/.local/lib/python3.7/site-packages/requests/sessions.py", line 587, in request
    resp = self.send(prep, **send_kwargs)
  File "/home/airflow/.local/lib/python3.7/site-packages/requests/sessions.py", line 701, in send
    r = adapter.send(request, **kwargs)
  File "/home/airflow/.local/lib/python3.7/site-packages/requests/adapters.py", line 547, in send
    raise ConnectionError(err, request=request)
requests.exceptions.ConnectionError: ('Connection aborted.', RemoteDisconnected('Remote end closed connection without response'))
[2023-02-25T00:36:13.031+0000] {taskinstance.py:1323} INFO - Marking task as FAILED. dag_id=cms_asp_noc, task_id=download_file, execution_date=20230224T000000, start_date=20230225T000241, end_date=20230225T003613
[2023-02-25T00:36:13.228+0000] {standard_task_runner.py:105} ERROR - Failed to execute job 1854 for task download_file (('Connection aborted.', RemoteDisconnected('Remote end closed connection without response')); 7536)
[2023-02-25T00:36:13.543+0000] {local_task_job.py:208} INFO - Task exited with return code 1
[2023-02-25T00:36:14.695+0000] {taskinstance.py:2578} INFO - 0 downstream tasks scheduled from follow-on schedule check
