[2023-02-08T12:52:36.293+0000] {taskinstance.py:1083} INFO - Dependencies all met for <TaskInstance: cms_asp_noc.website_changed scheduled__2022-01-30T00:00:00+00:00 [queued]>
[2023-02-08T12:52:36.766+0000] {taskinstance.py:1083} INFO - Dependencies all met for <TaskInstance: cms_asp_noc.website_changed scheduled__2022-01-30T00:00:00+00:00 [queued]>
[2023-02-08T12:52:36.777+0000] {taskinstance.py:1279} INFO - 
--------------------------------------------------------------------------------
[2023-02-08T12:52:36.779+0000] {taskinstance.py:1280} INFO - Starting attempt 1 of 1
[2023-02-08T12:52:36.781+0000] {taskinstance.py:1281} INFO - 
--------------------------------------------------------------------------------
[2023-02-08T12:52:37.523+0000] {taskinstance.py:1300} INFO - Executing <Task(PythonOperator): website_changed> on 2022-01-30 00:00:00+00:00
[2023-02-08T12:52:37.637+0000] {standard_task_runner.py:55} INFO - Started process 388 to run task
[2023-02-08T12:52:37.801+0000] {standard_task_runner.py:82} INFO - Running: ['***', 'tasks', 'run', 'cms_asp_noc', 'website_changed', 'scheduled__2022-01-30T00:00:00+00:00', '--job-id', '62', '--raw', '--subdir', 'DAGS_FOLDER/cms_upd.py', '--cfg-path', '/tmp/tmpla6a5b5t']
[2023-02-08T12:52:38.052+0000] {standard_task_runner.py:83} INFO - Job 62: Subtask website_changed
[2023-02-08T12:52:39.846+0000] {task_command.py:388} INFO - Running <TaskInstance: cms_asp_noc.website_changed scheduled__2022-01-30T00:00:00+00:00 [running]> on host 4ed7ae61ecf3
[2023-02-08T12:53:01.643+0000] {base_job.py:243} ERROR - LocalTaskJob heartbeat got an exception
Traceback (most recent call last):
  File "/home/airflow/.local/lib/python3.7/site-packages/sqlalchemy/engine/base.py", line 3361, in _wrap_pool_connect
    return fn()
  File "/home/airflow/.local/lib/python3.7/site-packages/sqlalchemy/pool/base.py", line 327, in connect
    return _ConnectionFairy._checkout(self)
  File "/home/airflow/.local/lib/python3.7/site-packages/sqlalchemy/pool/base.py", line 894, in _checkout
    fairy = _ConnectionRecord.checkout(pool)
  File "/home/airflow/.local/lib/python3.7/site-packages/sqlalchemy/pool/base.py", line 493, in checkout
    rec = pool._do_get()
  File "/home/airflow/.local/lib/python3.7/site-packages/sqlalchemy/pool/impl.py", line 256, in _do_get
    return self._create_connection()
  File "/home/airflow/.local/lib/python3.7/site-packages/sqlalchemy/pool/base.py", line 273, in _create_connection
    return _ConnectionRecord(self)
  File "/home/airflow/.local/lib/python3.7/site-packages/sqlalchemy/pool/base.py", line 388, in __init__
    self.__connect()
  File "/home/airflow/.local/lib/python3.7/site-packages/sqlalchemy/pool/base.py", line 691, in __connect
    pool.logger.debug("Error on connect(): %s", e)
  File "/home/airflow/.local/lib/python3.7/site-packages/sqlalchemy/util/langhelpers.py", line 72, in __exit__
    with_traceback=exc_tb,
  File "/home/airflow/.local/lib/python3.7/site-packages/sqlalchemy/util/compat.py", line 211, in raise_
    raise exception
  File "/home/airflow/.local/lib/python3.7/site-packages/sqlalchemy/pool/base.py", line 686, in __connect
    self.dbapi_connection = connection = pool._invoke_creator(self)
  File "/home/airflow/.local/lib/python3.7/site-packages/sqlalchemy/engine/create.py", line 578, in connect
    return dialect.connect(*cargs, **cparams)
  File "/home/airflow/.local/lib/python3.7/site-packages/sqlalchemy/engine/default.py", line 598, in connect
    return self.dbapi.connect(*cargs, **cparams)
  File "/home/airflow/.local/lib/python3.7/site-packages/psycopg2/__init__.py", line 122, in connect
    conn = _connect(dsn, connection_factory=connection_factory, **kwasync)
psycopg2.OperationalError: could not translate host name "postgres" to address: Temporary failure in name resolution


The above exception was the direct cause of the following exception:

Traceback (most recent call last):
  File "/home/airflow/.local/lib/python3.7/site-packages/airflow/jobs/base_job.py", line 215, in heartbeat
    session.merge(self)
  File "/home/airflow/.local/lib/python3.7/site-packages/sqlalchemy/orm/session.py", line 3057, in merge
    _resolve_conflict_map=_resolve_conflict_map,
  File "/home/airflow/.local/lib/python3.7/site-packages/sqlalchemy/orm/session.py", line 3135, in _merge
    options=options,
  File "/home/airflow/.local/lib/python3.7/site-packages/sqlalchemy/orm/session.py", line 2856, in get
    execution_options=execution_options,
  File "/home/airflow/.local/lib/python3.7/site-packages/sqlalchemy/orm/session.py", line 2974, in _get_impl
    load_options=load_options,
  File "/home/airflow/.local/lib/python3.7/site-packages/sqlalchemy/orm/loading.py", line 534, in load_on_pk_identity
    bind_arguments=bind_arguments,
  File "/home/airflow/.local/lib/python3.7/site-packages/sqlalchemy/orm/session.py", line 1713, in execute
    conn = self._connection_for_bind(bind)
  File "/home/airflow/.local/lib/python3.7/site-packages/sqlalchemy/orm/session.py", line 1553, in _connection_for_bind
    engine, execution_options
  File "/home/airflow/.local/lib/python3.7/site-packages/sqlalchemy/orm/session.py", line 747, in _connection_for_bind
    conn = bind.connect()
  File "/home/airflow/.local/lib/python3.7/site-packages/sqlalchemy/engine/base.py", line 3315, in connect
    return self._connection_cls(self, close_with_result=close_with_result)
  File "/home/airflow/.local/lib/python3.7/site-packages/sqlalchemy/engine/base.py", line 96, in __init__
    else engine.raw_connection()
  File "/home/airflow/.local/lib/python3.7/site-packages/sqlalchemy/engine/base.py", line 3394, in raw_connection
    return self._wrap_pool_connect(self.pool.connect, _connection)
  File "/home/airflow/.local/lib/python3.7/site-packages/sqlalchemy/engine/base.py", line 3365, in _wrap_pool_connect
    e, dialect, self
  File "/home/airflow/.local/lib/python3.7/site-packages/sqlalchemy/engine/base.py", line 2199, in _handle_dbapi_exception_noconnection
    sqlalchemy_exception, with_traceback=exc_info[2], from_=e
  File "/home/airflow/.local/lib/python3.7/site-packages/sqlalchemy/util/compat.py", line 211, in raise_
    raise exception
  File "/home/airflow/.local/lib/python3.7/site-packages/sqlalchemy/engine/base.py", line 3361, in _wrap_pool_connect
    return fn()
  File "/home/airflow/.local/lib/python3.7/site-packages/sqlalchemy/pool/base.py", line 327, in connect
    return _ConnectionFairy._checkout(self)
  File "/home/airflow/.local/lib/python3.7/site-packages/sqlalchemy/pool/base.py", line 894, in _checkout
    fairy = _ConnectionRecord.checkout(pool)
  File "/home/airflow/.local/lib/python3.7/site-packages/sqlalchemy/pool/base.py", line 493, in checkout
    rec = pool._do_get()
  File "/home/airflow/.local/lib/python3.7/site-packages/sqlalchemy/pool/impl.py", line 256, in _do_get
    return self._create_connection()
  File "/home/airflow/.local/lib/python3.7/site-packages/sqlalchemy/pool/base.py", line 273, in _create_connection
    return _ConnectionRecord(self)
  File "/home/airflow/.local/lib/python3.7/site-packages/sqlalchemy/pool/base.py", line 388, in __init__
    self.__connect()
  File "/home/airflow/.local/lib/python3.7/site-packages/sqlalchemy/pool/base.py", line 691, in __connect
    pool.logger.debug("Error on connect(): %s", e)
  File "/home/airflow/.local/lib/python3.7/site-packages/sqlalchemy/util/langhelpers.py", line 72, in __exit__
    with_traceback=exc_tb,
  File "/home/airflow/.local/lib/python3.7/site-packages/sqlalchemy/util/compat.py", line 211, in raise_
    raise exception
  File "/home/airflow/.local/lib/python3.7/site-packages/sqlalchemy/pool/base.py", line 686, in __connect
    self.dbapi_connection = connection = pool._invoke_creator(self)
  File "/home/airflow/.local/lib/python3.7/site-packages/sqlalchemy/engine/create.py", line 578, in connect
    return dialect.connect(*cargs, **cparams)
  File "/home/airflow/.local/lib/python3.7/site-packages/sqlalchemy/engine/default.py", line 598, in connect
    return self.dbapi.connect(*cargs, **cparams)
  File "/home/airflow/.local/lib/python3.7/site-packages/psycopg2/__init__.py", line 122, in connect
    conn = _connect(dsn, connection_factory=connection_factory, **kwasync)
sqlalchemy.exc.OperationalError: (psycopg2.OperationalError) could not translate host name "postgres" to address: Temporary failure in name resolution

(Background on this error at: https://sqlalche.me/e/14/e3q8)
[2023-02-08T12:53:08.467+0000] {taskinstance.py:1509} INFO - Exporting the following env vars:
AIRFLOW_CTX_DAG_OWNER=***
AIRFLOW_CTX_DAG_ID=cms_asp_noc
AIRFLOW_CTX_TASK_ID=website_changed
AIRFLOW_CTX_EXECUTION_DATE=2022-01-30T00:00:00+00:00
AIRFLOW_CTX_TRY_NUMBER=1
AIRFLOW_CTX_DAG_RUN_ID=scheduled__2022-01-30T00:00:00+00:00
[2023-02-08T12:53:10.025+0000] {logging_mixin.py:137} INFO - Website is changed. Links: True
[2023-02-08T12:53:10.057+0000] {python.py:177} INFO - Done. Returned value was: ['https://www.cms.gov/files/zip/april-2022-noc-pricing-file.zip', 'https://www.cms.gov/files/zip/july-2022-noc-pricing-file.zip', 'https://www.cms.gov/files/zip/april-2022-asp-ndc-hcpcs-crosswalk.zip', 'https://www.cms.gov/files/zip/october-2022-noc-pricing-file.zip', 'https://www.cms.gov/files/zip/july-2022-asp-pricing-file-updated-12142022.zip', 'https://www.cms.gov/files/zip/april-2022-asp-pricing-file-updated-12142022.zip', 'https://www.cms.gov/files/zip/january-2022-asp-ndc-hcpcs-crosswalk.zip', 'https://www.cms.gov/files/zip/january-2022-noc-pricing-file-updated-03022022.zip', 'https://www.cms.gov/files/zip/october-2022-asp-pricing-file-updated-12212022.zip', 'https://www.cms.gov/files/zip/january-2022-asp-pricing-file-updated-06082022.zip', 'https://www.cms.gov/files/zip/july-2022-asp-ndc-hcpcs-crosswalk-updated-07142022.zip']
[2023-02-08T12:53:11.086+0000] {taskinstance.py:1323} INFO - Marking task as SUCCESS. dag_id=cms_asp_noc, task_id=website_changed, execution_date=20220130T000000, start_date=20230208T125236, end_date=20230208T125311
[2023-02-08T12:53:17.584+0000] {local_task_job.py:273} WARNING - State of this instance has been externally set to success. Terminating instance.
[2023-02-08T12:53:17.792+0000] {process_utils.py:133} INFO - Sending Signals.SIGTERM to group 388. PIDs of all processes in the group: [388]
[2023-02-08T12:53:17.870+0000] {process_utils.py:84} INFO - Sending the signal Signals.SIGTERM to group 388
[2023-02-08T12:53:18.848+0000] {process_utils.py:79} INFO - Process psutil.Process(pid=388, status='terminated', exitcode=0, started='12:52:37') (388) terminated with exit code 0
