[2023-02-10T12:19:05.071+0000] {taskinstance.py:1083} INFO - Dependencies all met for <TaskInstance: cms_asp_noc.load_test scheduled__2022-05-11T00:00:00+00:00 [queued]>
[2023-02-10T12:19:05.295+0000] {taskinstance.py:1083} INFO - Dependencies all met for <TaskInstance: cms_asp_noc.load_test scheduled__2022-05-11T00:00:00+00:00 [queued]>
[2023-02-10T12:19:05.299+0000] {taskinstance.py:1279} INFO - 
--------------------------------------------------------------------------------
[2023-02-10T12:19:05.310+0000] {taskinstance.py:1280} INFO - Starting attempt 1 of 1
[2023-02-10T12:19:05.319+0000] {taskinstance.py:1281} INFO - 
--------------------------------------------------------------------------------
[2023-02-10T12:19:05.570+0000] {taskinstance.py:1300} INFO - Executing <Task(PythonOperator): load_test> on 2022-05-11 00:00:00+00:00
[2023-02-10T12:19:05.850+0000] {standard_task_runner.py:55} INFO - Started process 32427 to run task
[2023-02-10T12:19:06.084+0000] {standard_task_runner.py:82} INFO - Running: ['***', 'tasks', 'run', 'cms_asp_noc', 'load_test', 'scheduled__2022-05-11T00:00:00+00:00', '--job-id', '1639', '--raw', '--subdir', 'DAGS_FOLDER/cms_upd.py', '--cfg-path', '/tmp/tmp5iujwruw']
[2023-02-10T12:19:06.148+0000] {standard_task_runner.py:83} INFO - Job 1639: Subtask load_test
[2023-02-10T12:19:08.144+0000] {task_command.py:388} INFO - Running <TaskInstance: cms_asp_noc.load_test scheduled__2022-05-11T00:00:00+00:00 [running]> on host 2886274f27ea
[2023-02-10T12:19:10.691+0000] {taskinstance.py:1509} INFO - Exporting the following env vars:
AIRFLOW_CTX_DAG_OWNER=***
AIRFLOW_CTX_DAG_ID=cms_asp_noc
AIRFLOW_CTX_TASK_ID=load_test
AIRFLOW_CTX_EXECUTION_DATE=2022-05-11T00:00:00+00:00
AIRFLOW_CTX_TRY_NUMBER=1
AIRFLOW_CTX_DAG_RUN_ID=scheduled__2022-05-11T00:00:00+00:00
[2023-02-10T12:19:11.551+0000] {taskinstance.py:1768} ERROR - Task failed with exception
Traceback (most recent call last):
  File "/home/airflow/.local/lib/python3.7/site-packages/airflow/operators/python.py", line 175, in execute
    return_value = self.execute_callable()
  File "/home/airflow/.local/lib/python3.7/site-packages/airflow/operators/python.py", line 192, in execute_callable
    return self.python_callable(*self.op_args, **self.op_kwargs)
  File "/opt/airflow/dags/cms_pg/load_test.py", line 19, in load_test
    cur.execute("select * from student")
psycopg2.errors.UndefinedTable: relation "student" does not exist
LINE 1: select * from student
                      ^

[2023-02-10T12:19:33.124+0000] {taskinstance.py:1323} INFO - Marking task as FAILED. dag_id=cms_asp_noc, task_id=load_test, execution_date=20220511T000000, start_date=20230210T121905, end_date=20230210T121932
[2023-02-10T12:19:33.489+0000] {standard_task_runner.py:105} ERROR - Failed to execute job 1639 for task load_test (relation "student" does not exist
LINE 1: select * from student
                      ^
; 32427)
[2023-02-10T12:19:36.961+0000] {local_task_job.py:208} INFO - Task exited with return code 1
[2023-02-10T12:19:37.485+0000] {taskinstance.py:2578} INFO - 0 downstream tasks scheduled from follow-on schedule check
