[2023-02-10T12:19:39.778+0000] {taskinstance.py:1083} INFO - Dependencies all met for <TaskInstance: cms_asp_noc.load_test scheduled__2022-05-13T00:00:00+00:00 [queued]>
[2023-02-10T12:19:39.794+0000] {taskinstance.py:1083} INFO - Dependencies all met for <TaskInstance: cms_asp_noc.load_test scheduled__2022-05-13T00:00:00+00:00 [queued]>
[2023-02-10T12:19:39.795+0000] {taskinstance.py:1279} INFO - 
--------------------------------------------------------------------------------
[2023-02-10T12:19:39.796+0000] {taskinstance.py:1280} INFO - Starting attempt 1 of 1
[2023-02-10T12:19:39.797+0000] {taskinstance.py:1281} INFO - 
--------------------------------------------------------------------------------
[2023-02-10T12:19:39.830+0000] {taskinstance.py:1300} INFO - Executing <Task(PythonOperator): load_test> on 2022-05-13 00:00:00+00:00
[2023-02-10T12:19:39.848+0000] {standard_task_runner.py:55} INFO - Started process 32456 to run task
[2023-02-10T12:19:39.881+0000] {standard_task_runner.py:82} INFO - Running: ['***', 'tasks', 'run', 'cms_asp_noc', 'load_test', 'scheduled__2022-05-13T00:00:00+00:00', '--job-id', '1644', '--raw', '--subdir', 'DAGS_FOLDER/cms_upd.py', '--cfg-path', '/tmp/tmp0xi37ahi']
[2023-02-10T12:19:39.894+0000] {standard_task_runner.py:83} INFO - Job 1644: Subtask load_test
[2023-02-10T12:19:40.083+0000] {task_command.py:388} INFO - Running <TaskInstance: cms_asp_noc.load_test scheduled__2022-05-13T00:00:00+00:00 [running]> on host 2886274f27ea
[2023-02-10T12:19:40.204+0000] {taskinstance.py:1509} INFO - Exporting the following env vars:
AIRFLOW_CTX_DAG_OWNER=***
AIRFLOW_CTX_DAG_ID=cms_asp_noc
AIRFLOW_CTX_TASK_ID=load_test
AIRFLOW_CTX_EXECUTION_DATE=2022-05-13T00:00:00+00:00
AIRFLOW_CTX_TRY_NUMBER=1
AIRFLOW_CTX_DAG_RUN_ID=scheduled__2022-05-13T00:00:00+00:00
[2023-02-10T12:19:40.218+0000] {taskinstance.py:1768} ERROR - Task failed with exception
Traceback (most recent call last):
  File "/home/airflow/.local/lib/python3.7/site-packages/airflow/operators/python.py", line 175, in execute
    return_value = self.execute_callable()
  File "/home/airflow/.local/lib/python3.7/site-packages/airflow/operators/python.py", line 192, in execute_callable
    return self.python_callable(*self.op_args, **self.op_kwargs)
  File "/opt/airflow/dags/cms_pg/load_test.py", line 19, in load_test
    cur.execute("select * from student")
psycopg2.errors.UndefinedTable: relation "student" does not exist
LINE 1: select * from student
                      ^

[2023-02-10T12:19:40.247+0000] {taskinstance.py:1323} INFO - Marking task as FAILED. dag_id=cms_asp_noc, task_id=load_test, execution_date=20220513T000000, start_date=20230210T121939, end_date=20230210T121940
[2023-02-10T12:19:40.268+0000] {standard_task_runner.py:105} ERROR - Failed to execute job 1644 for task load_test (relation "student" does not exist
LINE 1: select * from student
                      ^
; 32456)
[2023-02-10T12:19:40.313+0000] {local_task_job.py:208} INFO - Task exited with return code 1
[2023-02-10T12:19:40.341+0000] {taskinstance.py:2578} INFO - 0 downstream tasks scheduled from follow-on schedule check
