[2023-02-08T13:08:16.933+0000] {taskinstance.py:1083} INFO - Dependencies all met for <TaskInstance: cms_asp_noc.download_file scheduled__2022-03-26T00:00:00+00:00 [queued]>
[2023-02-08T13:08:17.175+0000] {taskinstance.py:1083} INFO - Dependencies all met for <TaskInstance: cms_asp_noc.download_file scheduled__2022-03-26T00:00:00+00:00 [queued]>
[2023-02-08T13:08:17.217+0000] {taskinstance.py:1279} INFO - 
--------------------------------------------------------------------------------
[2023-02-08T13:08:17.219+0000] {taskinstance.py:1280} INFO - Starting attempt 1 of 1
[2023-02-08T13:08:17.226+0000] {taskinstance.py:1281} INFO - 
--------------------------------------------------------------------------------
[2023-02-08T13:08:17.757+0000] {taskinstance.py:1300} INFO - Executing <Task(PythonOperator): download_file> on 2022-03-26 00:00:00+00:00
[2023-02-08T13:08:18.032+0000] {standard_task_runner.py:55} INFO - Started process 1099 to run task
[2023-02-08T13:08:18.155+0000] {standard_task_runner.py:82} INFO - Running: ['***', 'tasks', 'run', 'cms_asp_noc', 'download_file', 'scheduled__2022-03-26T00:00:00+00:00', '--job-id', '164', '--raw', '--subdir', 'DAGS_FOLDER/cms_upd.py', '--cfg-path', '/tmp/tmp6x_sd7k_']
[2023-02-08T13:08:18.284+0000] {standard_task_runner.py:83} INFO - Job 164: Subtask download_file
[2023-02-08T13:08:18.862+0000] {task_command.py:388} INFO - Running <TaskInstance: cms_asp_noc.download_file scheduled__2022-03-26T00:00:00+00:00 [running]> on host 4ed7ae61ecf3
[2023-02-08T13:09:15.242+0000] {taskinstance.py:1509} INFO - Exporting the following env vars:
AIRFLOW_CTX_DAG_OWNER=***
AIRFLOW_CTX_DAG_ID=cms_asp_noc
AIRFLOW_CTX_TASK_ID=download_file
AIRFLOW_CTX_EXECUTION_DATE=2022-03-26T00:00:00+00:00
AIRFLOW_CTX_TRY_NUMBER=1
AIRFLOW_CTX_DAG_RUN_ID=scheduled__2022-03-26T00:00:00+00:00
[2023-02-08T13:09:24.237+0000] {logging_mixin.py:137} INFO - october-2022-noc-pricing-file.zip is downloaded.
[2023-02-08T13:09:26.059+0000] {logging_mixin.py:137} INFO - april-2022-noc-pricing-file.zip is downloaded.
[2023-02-08T13:09:29.595+0000] {logging_mixin.py:137} INFO - 2023.zip is downloaded.
[2023-02-08T13:09:31.032+0000] {logging_mixin.py:137} INFO - 2023.zip is downloaded.
[2023-02-08T13:09:56.502+0000] {taskinstance.py:1768} ERROR - Task failed with exception
Traceback (most recent call last):
  File "/home/airflow/.local/lib/python3.7/site-packages/urllib3/connectionpool.py", line 710, in urlopen
    chunked=chunked,
  File "/home/airflow/.local/lib/python3.7/site-packages/urllib3/connectionpool.py", line 449, in _make_request
    six.raise_from(e, None)
  File "<string>", line 3, in raise_from
  File "/home/airflow/.local/lib/python3.7/site-packages/urllib3/connectionpool.py", line 444, in _make_request
    httplib_response = conn.getresponse()
  File "/usr/local/lib/python3.7/http/client.py", line 1373, in getresponse
    response.begin()
  File "/usr/local/lib/python3.7/http/client.py", line 319, in begin
    version, status, reason = self._read_status()
  File "/usr/local/lib/python3.7/http/client.py", line 288, in _read_status
    raise RemoteDisconnected("Remote end closed connection without"
http.client.RemoteDisconnected: Remote end closed connection without response

During handling of the above exception, another exception occurred:

Traceback (most recent call last):
  File "/home/airflow/.local/lib/python3.7/site-packages/requests/adapters.py", line 499, in send
    timeout=timeout,
  File "/home/airflow/.local/lib/python3.7/site-packages/urllib3/connectionpool.py", line 788, in urlopen
    method, url, error=e, _pool=self, _stacktrace=sys.exc_info()[2]
  File "/home/airflow/.local/lib/python3.7/site-packages/urllib3/util/retry.py", line 550, in increment
    raise six.reraise(type(error), error, _stacktrace)
  File "/home/airflow/.local/lib/python3.7/site-packages/urllib3/packages/six.py", line 769, in reraise
    raise value.with_traceback(tb)
  File "/home/airflow/.local/lib/python3.7/site-packages/urllib3/connectionpool.py", line 710, in urlopen
    chunked=chunked,
  File "/home/airflow/.local/lib/python3.7/site-packages/urllib3/connectionpool.py", line 449, in _make_request
    six.raise_from(e, None)
  File "<string>", line 3, in raise_from
  File "/home/airflow/.local/lib/python3.7/site-packages/urllib3/connectionpool.py", line 444, in _make_request
    httplib_response = conn.getresponse()
  File "/usr/local/lib/python3.7/http/client.py", line 1373, in getresponse
    response.begin()
  File "/usr/local/lib/python3.7/http/client.py", line 319, in begin
    version, status, reason = self._read_status()
  File "/usr/local/lib/python3.7/http/client.py", line 288, in _read_status
    raise RemoteDisconnected("Remote end closed connection without"
urllib3.exceptions.ProtocolError: ('Connection aborted.', RemoteDisconnected('Remote end closed connection without response'))

During handling of the above exception, another exception occurred:

Traceback (most recent call last):
  File "/home/airflow/.local/lib/python3.7/site-packages/airflow/operators/python.py", line 175, in execute
    return_value = self.execute_callable()
  File "/home/airflow/.local/lib/python3.7/site-packages/airflow/operators/python.py", line 192, in execute_callable
    return self.python_callable(*self.op_args, **self.op_kwargs)
  File "/opt/airflow/dags/cms_pg/download_new_files.py", line 49, in download_zip_files
    response = requests.get(url)
  File "/home/airflow/.local/lib/python3.7/site-packages/requests/api.py", line 73, in get
    return request("get", url, params=params, **kwargs)
  File "/home/airflow/.local/lib/python3.7/site-packages/requests/api.py", line 59, in request
    return session.request(method=method, url=url, **kwargs)
  File "/home/airflow/.local/lib/python3.7/site-packages/requests/sessions.py", line 587, in request
    resp = self.send(prep, **send_kwargs)
  File "/home/airflow/.local/lib/python3.7/site-packages/requests/sessions.py", line 701, in send
    r = adapter.send(request, **kwargs)
  File "/home/airflow/.local/lib/python3.7/site-packages/requests/adapters.py", line 547, in send
    raise ConnectionError(err, request=request)
requests.exceptions.ConnectionError: ('Connection aborted.', RemoteDisconnected('Remote end closed connection without response'))
[2023-02-08T13:09:58.404+0000] {taskinstance.py:1323} INFO - Marking task as FAILED. dag_id=cms_asp_noc, task_id=download_file, execution_date=20220326T000000, start_date=20230208T130817, end_date=20230208T130958
[2023-02-08T13:10:00.546+0000] {standard_task_runner.py:105} ERROR - Failed to execute job 164 for task download_file (('Connection aborted.', RemoteDisconnected('Remote end closed connection without response')); 1099)
[2023-02-08T13:10:03.247+0000] {local_task_job.py:208} INFO - Task exited with return code 1
[2023-02-08T13:10:30.007+0000] {taskinstance.py:2578} INFO - 0 downstream tasks scheduled from follow-on schedule check
