[2023-02-10T13:04:39.339+0000] {taskinstance.py:1083} INFO - Dependencies all met for <TaskInstance: cms_asp_noc.load_test manual__2023-02-10T12:20:42.866622+00:00 [queued]>
[2023-02-10T13:04:39.351+0000] {taskinstance.py:1083} INFO - Dependencies all met for <TaskInstance: cms_asp_noc.load_test manual__2023-02-10T12:20:42.866622+00:00 [queued]>
[2023-02-10T13:04:39.351+0000] {taskinstance.py:1279} INFO - 
--------------------------------------------------------------------------------
[2023-02-10T13:04:39.352+0000] {taskinstance.py:1280} INFO - Starting attempt 6 of 6
[2023-02-10T13:04:39.353+0000] {taskinstance.py:1281} INFO - 
--------------------------------------------------------------------------------
[2023-02-10T13:04:39.367+0000] {taskinstance.py:1300} INFO - Executing <Task(PythonOperator): load_test> on 2023-02-10 12:20:42.866622+00:00
[2023-02-10T13:04:39.392+0000] {standard_task_runner.py:55} INFO - Started process 35159 to run task
[2023-02-10T13:04:39.399+0000] {standard_task_runner.py:82} INFO - Running: ['***', 'tasks', 'run', 'cms_asp_noc', 'load_test', 'manual__2023-02-10T12:20:42.866622+00:00', '--job-id', '1660', '--raw', '--subdir', 'DAGS_FOLDER/cms_upd.py', '--cfg-path', '/tmp/tmpu_4eclws']
[2023-02-10T13:04:39.404+0000] {standard_task_runner.py:83} INFO - Job 1660: Subtask load_test
[2023-02-10T13:04:39.516+0000] {task_command.py:388} INFO - Running <TaskInstance: cms_asp_noc.load_test manual__2023-02-10T12:20:42.866622+00:00 [running]> on host 2886274f27ea
[2023-02-10T13:04:39.614+0000] {taskinstance.py:1509} INFO - Exporting the following env vars:
AIRFLOW_CTX_DAG_OWNER=***
AIRFLOW_CTX_DAG_ID=cms_asp_noc
AIRFLOW_CTX_TASK_ID=load_test
AIRFLOW_CTX_EXECUTION_DATE=2023-02-10T12:20:42.866622+00:00
AIRFLOW_CTX_TRY_NUMBER=6
AIRFLOW_CTX_DAG_RUN_ID=manual__2023-02-10T12:20:42.866622+00:00
[2023-02-10T13:04:40.192+0000] {taskinstance.py:1768} ERROR - Task failed with exception
Traceback (most recent call last):
  File "/home/airflow/.local/lib/python3.7/site-packages/airflow/operators/python.py", line 175, in execute
    return_value = self.execute_callable()
  File "/home/airflow/.local/lib/python3.7/site-packages/airflow/operators/python.py", line 192, in execute_callable
    return self.python_callable(*self.op_args, **self.op_kwargs)
  File "/opt/airflow/dags/cms_pg/load_test.py", line 33, in test2_load
    db = create_engine(conn_string)
  File "<string>", line 2, in create_engine
  File "/home/airflow/.local/lib/python3.7/site-packages/sqlalchemy/util/deprecations.py", line 375, in warned
    return fn(*args, **kwargs)
  File "/home/airflow/.local/lib/python3.7/site-packages/sqlalchemy/engine/create.py", line 522, in create_engine
    entrypoint = u._get_entrypoint()
  File "/home/airflow/.local/lib/python3.7/site-packages/sqlalchemy/engine/url.py", line 662, in _get_entrypoint
    cls = registry.load(name)
  File "/home/airflow/.local/lib/python3.7/site-packages/sqlalchemy/util/langhelpers.py", line 344, in load
    "Can't load plugin: %s:%s" % (self.group, name)
sqlalchemy.exc.NoSuchModuleError: Can't load plugin: sqlalchemy.dialects:***
[2023-02-10T13:04:40.215+0000] {taskinstance.py:1323} INFO - Marking task as FAILED. dag_id=cms_asp_noc, task_id=load_test, execution_date=20230210T122042, start_date=20230210T130439, end_date=20230210T130440
[2023-02-10T13:04:40.229+0000] {standard_task_runner.py:105} ERROR - Failed to execute job 1660 for task load_test (Can't load plugin: sqlalchemy.dialects:***; 35159)
[2023-02-10T13:04:40.301+0000] {local_task_job.py:208} INFO - Task exited with return code 1
[2023-02-10T13:04:40.419+0000] {taskinstance.py:2578} INFO - 0 downstream tasks scheduled from follow-on schedule check
