[2023-02-10T12:20:56.743+0000] {taskinstance.py:1083} INFO - Dependencies all met for <TaskInstance: cms_asp_noc.load_test manual__2023-02-10T12:20:42.866622+00:00 [queued]>
[2023-02-10T12:20:56.758+0000] {taskinstance.py:1083} INFO - Dependencies all met for <TaskInstance: cms_asp_noc.load_test manual__2023-02-10T12:20:42.866622+00:00 [queued]>
[2023-02-10T12:20:56.759+0000] {taskinstance.py:1279} INFO - 
--------------------------------------------------------------------------------
[2023-02-10T12:20:56.760+0000] {taskinstance.py:1280} INFO - Starting attempt 1 of 1
[2023-02-10T12:20:56.760+0000] {taskinstance.py:1281} INFO - 
--------------------------------------------------------------------------------
[2023-02-10T12:20:56.783+0000] {taskinstance.py:1300} INFO - Executing <Task(PythonOperator): load_test> on 2023-02-10 12:20:42.866622+00:00
[2023-02-10T12:20:56.807+0000] {standard_task_runner.py:55} INFO - Started process 32546 to run task
[2023-02-10T12:20:56.812+0000] {standard_task_runner.py:82} INFO - Running: ['***', 'tasks', 'run', 'cms_asp_noc', 'load_test', 'manual__2023-02-10T12:20:42.866622+00:00', '--job-id', '1648', '--raw', '--subdir', 'DAGS_FOLDER/cms_upd.py', '--cfg-path', '/tmp/tmpfwtag4j6']
[2023-02-10T12:20:56.817+0000] {standard_task_runner.py:83} INFO - Job 1648: Subtask load_test
[2023-02-10T12:20:57.007+0000] {task_command.py:388} INFO - Running <TaskInstance: cms_asp_noc.load_test manual__2023-02-10T12:20:42.866622+00:00 [running]> on host 2886274f27ea
[2023-02-10T12:20:57.113+0000] {taskinstance.py:1509} INFO - Exporting the following env vars:
AIRFLOW_CTX_DAG_OWNER=***
AIRFLOW_CTX_DAG_ID=cms_asp_noc
AIRFLOW_CTX_TASK_ID=load_test
AIRFLOW_CTX_EXECUTION_DATE=2023-02-10T12:20:42.866622+00:00
AIRFLOW_CTX_TRY_NUMBER=1
AIRFLOW_CTX_DAG_RUN_ID=manual__2023-02-10T12:20:42.866622+00:00
[2023-02-10T12:20:57.120+0000] {taskinstance.py:1768} ERROR - Task failed with exception
Traceback (most recent call last):
  File "/home/airflow/.local/lib/python3.7/site-packages/airflow/operators/python.py", line 175, in execute
    return_value = self.execute_callable()
  File "/home/airflow/.local/lib/python3.7/site-packages/airflow/operators/python.py", line 192, in execute_callable
    return self.python_callable(*self.op_args, **self.op_kwargs)
  File "/opt/airflow/dags/cms_pg/load_test.py", line 19, in load_test
    cur.execute("select * from student")
psycopg2.errors.UndefinedTable: relation "student" does not exist
LINE 1: select * from student
                      ^

[2023-02-10T12:20:57.134+0000] {taskinstance.py:1323} INFO - Marking task as FAILED. dag_id=cms_asp_noc, task_id=load_test, execution_date=20230210T122042, start_date=20230210T122056, end_date=20230210T122057
[2023-02-10T12:20:57.993+0000] {standard_task_runner.py:105} ERROR - Failed to execute job 1648 for task load_test (relation "student" does not exist
LINE 1: select * from student
                      ^
; 32546)
[2023-02-10T12:20:58.086+0000] {local_task_job.py:208} INFO - Task exited with return code 1
[2023-02-10T12:20:58.156+0000] {taskinstance.py:2578} INFO - 0 downstream tasks scheduled from follow-on schedule check
