[2023-02-10T13:51:39.300+0000] {taskinstance.py:1083} INFO - Dependencies all met for <TaskInstance: cms_asp_noc.data_load manual__2023-02-10T12:22:58.859123+00:00 [queued]>
[2023-02-10T13:51:39.312+0000] {taskinstance.py:1083} INFO - Dependencies all met for <TaskInstance: cms_asp_noc.data_load manual__2023-02-10T12:22:58.859123+00:00 [queued]>
[2023-02-10T13:51:39.313+0000] {taskinstance.py:1279} INFO - 
--------------------------------------------------------------------------------
[2023-02-10T13:51:39.313+0000] {taskinstance.py:1280} INFO - Starting attempt 4 of 4
[2023-02-10T13:51:39.314+0000] {taskinstance.py:1281} INFO - 
--------------------------------------------------------------------------------
[2023-02-10T13:51:39.323+0000] {taskinstance.py:1300} INFO - Executing <Task(PythonOperator): data_load> on 2023-02-10 12:22:58.859123+00:00
[2023-02-10T13:51:39.333+0000] {standard_task_runner.py:55} INFO - Started process 37342 to run task
[2023-02-10T13:51:39.337+0000] {standard_task_runner.py:82} INFO - Running: ['***', 'tasks', 'run', 'cms_asp_noc', 'data_load', 'manual__2023-02-10T12:22:58.859123+00:00', '--job-id', '1664', '--raw', '--subdir', 'DAGS_FOLDER/cms_upd.py', '--cfg-path', '/tmp/tmp7lav9jex']
[2023-02-10T13:51:39.341+0000] {standard_task_runner.py:83} INFO - Job 1664: Subtask data_load
[2023-02-10T13:51:39.444+0000] {task_command.py:388} INFO - Running <TaskInstance: cms_asp_noc.data_load manual__2023-02-10T12:22:58.859123+00:00 [running]> on host 2886274f27ea
[2023-02-10T13:51:39.529+0000] {taskinstance.py:1509} INFO - Exporting the following env vars:
AIRFLOW_CTX_DAG_OWNER=***
AIRFLOW_CTX_DAG_ID=cms_asp_noc
AIRFLOW_CTX_TASK_ID=data_load
AIRFLOW_CTX_EXECUTION_DATE=2023-02-10T12:22:58.859123+00:00
AIRFLOW_CTX_TRY_NUMBER=4
AIRFLOW_CTX_DAG_RUN_ID=manual__2023-02-10T12:22:58.859123+00:00
[2023-02-10T13:51:39.534+0000] {logging_mixin.py:137} INFO - ['section 508 version of April 2022 ASP Pricing File updated 060222.csv', 'section 508 version of April 2022 ASP Pricing File updated 120222.csv', 'section 508 version of COVID_19_NDC_HCPCS_Crosswalk.csv', 'section 508 version of January 2022 ASP Pricing File updated 060222.csv', 'section 508 version of July 2022 ASP NDC-HCPCS Crosswalk 060722.csv', 'section 508 version of July 2022 ASP Pricing File updated 120222.csv', 'section 508 version of July 2022 AWP NDC-HCPCS Crosswalk_060722.csv', 'section 508 version of July 2022 NOC NDC-HCPCS Crosswalk 060722.csv', 'section 508 version of July 2022 NOC Pricing File 060722.csv', 'section 508 version of July 2022 OPPS NDC-HCPCS Crosswalk 060722.csv', 'section 508 version of NDC-HCPCS Crosswalk Introduction Text 060722.csv']
[2023-02-10T13:51:39.535+0000] {logging_mixin.py:137} INFO - /opt/***/op_files/cms_zip_files/section 508 version of April 2022 ASP Pricing File updated 060222.csv
[2023-02-10T13:51:40.037+0000] {logging_mixin.py:137} INFO - success
[2023-02-10T13:51:40.038+0000] {logging_mixin.py:137} INFO - section 508 version of April 2022 ASP Pricing File updated 060222.csv
[2023-02-10T13:51:40.039+0000] {logging_mixin.py:137} INFO - excel file has been cleaned
[2023-02-10T13:51:40.071+0000] {logging_mixin.py:137} INFO -     Date_Uploaded HCPCS_Code  ...    modification_time quarter
0      2023-02-10      90371  ...  2022-06-02 10:10:10       2
1      2023-02-10      90375  ...  2022-06-02 10:10:10       2
2      2023-02-10      90376  ...  2022-06-02 10:10:10       2
3      2023-02-10      90377  ...  2022-06-02 10:10:10       2
4      2023-02-10      90586  ...  2022-06-02 10:10:10       2
..            ...        ...  ...                  ...     ...
641    2023-02-10      Q9965  ...  2022-06-02 10:10:10       2
642    2023-02-10      Q9966  ...  2022-06-02 10:10:10       2
643    2023-02-10      Q9967  ...  2022-06-02 10:10:10       2
644    2023-02-10      Q9991  ...  2022-06-02 10:10:10       2
645    2023-02-10      Q9992  ...  2022-06-02 10:10:10       2

[646 rows x 14 columns]
[2023-02-10T13:51:40.077+0000] {taskinstance.py:1768} ERROR - Task failed with exception
Traceback (most recent call last):
  File "/home/airflow/.local/lib/python3.7/site-packages/sqlalchemy/engine/base.py", line 3361, in _wrap_pool_connect
    return fn()
  File "/home/airflow/.local/lib/python3.7/site-packages/sqlalchemy/pool/base.py", line 327, in connect
    return _ConnectionFairy._checkout(self)
  File "/home/airflow/.local/lib/python3.7/site-packages/sqlalchemy/pool/base.py", line 894, in _checkout
    fairy = _ConnectionRecord.checkout(pool)
  File "/home/airflow/.local/lib/python3.7/site-packages/sqlalchemy/pool/base.py", line 493, in checkout
    rec = pool._do_get()
  File "/home/airflow/.local/lib/python3.7/site-packages/sqlalchemy/pool/impl.py", line 146, in _do_get
    self._dec_overflow()
  File "/home/airflow/.local/lib/python3.7/site-packages/sqlalchemy/util/langhelpers.py", line 72, in __exit__
    with_traceback=exc_tb,
  File "/home/airflow/.local/lib/python3.7/site-packages/sqlalchemy/util/compat.py", line 211, in raise_
    raise exception
  File "/home/airflow/.local/lib/python3.7/site-packages/sqlalchemy/pool/impl.py", line 143, in _do_get
    return self._create_connection()
  File "/home/airflow/.local/lib/python3.7/site-packages/sqlalchemy/pool/base.py", line 273, in _create_connection
    return _ConnectionRecord(self)
  File "/home/airflow/.local/lib/python3.7/site-packages/sqlalchemy/pool/base.py", line 388, in __init__
    self.__connect()
  File "/home/airflow/.local/lib/python3.7/site-packages/sqlalchemy/pool/base.py", line 691, in __connect
    pool.logger.debug("Error on connect(): %s", e)
  File "/home/airflow/.local/lib/python3.7/site-packages/sqlalchemy/util/langhelpers.py", line 72, in __exit__
    with_traceback=exc_tb,
  File "/home/airflow/.local/lib/python3.7/site-packages/sqlalchemy/util/compat.py", line 211, in raise_
    raise exception
  File "/home/airflow/.local/lib/python3.7/site-packages/sqlalchemy/pool/base.py", line 686, in __connect
    self.dbapi_connection = connection = pool._invoke_creator(self)
  File "/home/airflow/.local/lib/python3.7/site-packages/sqlalchemy/engine/create.py", line 578, in connect
    return dialect.connect(*cargs, **cparams)
  File "/home/airflow/.local/lib/python3.7/site-packages/sqlalchemy/engine/default.py", line 598, in connect
    return self.dbapi.connect(*cargs, **cparams)
  File "/home/airflow/.local/lib/python3.7/site-packages/psycopg2/__init__.py", line 122, in connect
    conn = _connect(dsn, connection_factory=connection_factory, **kwasync)
psycopg2.OperationalError: could not connect to server: No such file or directory
	Is the server running locally and accepting
	connections on Unix domain socket "/var/run/postgresql/.s.PGSQL.5432"?


The above exception was the direct cause of the following exception:

Traceback (most recent call last):
  File "/home/airflow/.local/lib/python3.7/site-packages/airflow/operators/python.py", line 175, in execute
    return_value = self.execute_callable()
  File "/home/airflow/.local/lib/python3.7/site-packages/airflow/operators/python.py", line 192, in execute_callable
    return self.python_callable(*self.op_args, **self.op_kwargs)
  File "/opt/airflow/dags/cms_pg/data_load_pg.py", line 112, in data_load_pg
    df.to_sql(table_name, engine_names, if_exists= 'replace', index= False)
  File "/home/airflow/.local/lib/python3.7/site-packages/pandas/core/generic.py", line 2882, in to_sql
    method=method,
  File "/home/airflow/.local/lib/python3.7/site-packages/pandas/io/sql.py", line 728, in to_sql
    **engine_kwargs,
  File "/home/airflow/.local/lib/python3.7/site-packages/pandas/io/sql.py", line 1758, in to_sql
    dtype=dtype,
  File "/home/airflow/.local/lib/python3.7/site-packages/pandas/io/sql.py", line 1650, in prep_table
    table.create()
  File "/home/airflow/.local/lib/python3.7/site-packages/pandas/io/sql.py", line 856, in create
    if self.exists():
  File "/home/airflow/.local/lib/python3.7/site-packages/pandas/io/sql.py", line 840, in exists
    return self.pd_sql.has_table(self.name, self.schema)
  File "/home/airflow/.local/lib/python3.7/site-packages/pandas/io/sql.py", line 1783, in has_table
    insp = sa.inspect(self.connectable)
  File "/home/airflow/.local/lib/python3.7/site-packages/sqlalchemy/inspection.py", line 64, in inspect
    ret = reg(subject)
  File "/home/airflow/.local/lib/python3.7/site-packages/sqlalchemy/engine/reflection.py", line 182, in _engine_insp
    return Inspector._construct(Inspector._init_engine, bind)
  File "/home/airflow/.local/lib/python3.7/site-packages/sqlalchemy/engine/reflection.py", line 117, in _construct
    init(self, bind)
  File "/home/airflow/.local/lib/python3.7/site-packages/sqlalchemy/engine/reflection.py", line 128, in _init_engine
    engine.connect().close()
  File "/home/airflow/.local/lib/python3.7/site-packages/sqlalchemy/engine/base.py", line 3315, in connect
    return self._connection_cls(self, close_with_result=close_with_result)
  File "/home/airflow/.local/lib/python3.7/site-packages/sqlalchemy/engine/base.py", line 96, in __init__
    else engine.raw_connection()
  File "/home/airflow/.local/lib/python3.7/site-packages/sqlalchemy/engine/base.py", line 3394, in raw_connection
    return self._wrap_pool_connect(self.pool.connect, _connection)
  File "/home/airflow/.local/lib/python3.7/site-packages/sqlalchemy/engine/base.py", line 3365, in _wrap_pool_connect
    e, dialect, self
  File "/home/airflow/.local/lib/python3.7/site-packages/sqlalchemy/engine/base.py", line 2199, in _handle_dbapi_exception_noconnection
    sqlalchemy_exception, with_traceback=exc_info[2], from_=e
  File "/home/airflow/.local/lib/python3.7/site-packages/sqlalchemy/util/compat.py", line 211, in raise_
    raise exception
  File "/home/airflow/.local/lib/python3.7/site-packages/sqlalchemy/engine/base.py", line 3361, in _wrap_pool_connect
    return fn()
  File "/home/airflow/.local/lib/python3.7/site-packages/sqlalchemy/pool/base.py", line 327, in connect
    return _ConnectionFairy._checkout(self)
  File "/home/airflow/.local/lib/python3.7/site-packages/sqlalchemy/pool/base.py", line 894, in _checkout
    fairy = _ConnectionRecord.checkout(pool)
  File "/home/airflow/.local/lib/python3.7/site-packages/sqlalchemy/pool/base.py", line 493, in checkout
    rec = pool._do_get()
  File "/home/airflow/.local/lib/python3.7/site-packages/sqlalchemy/pool/impl.py", line 146, in _do_get
    self._dec_overflow()
  File "/home/airflow/.local/lib/python3.7/site-packages/sqlalchemy/util/langhelpers.py", line 72, in __exit__
    with_traceback=exc_tb,
  File "/home/airflow/.local/lib/python3.7/site-packages/sqlalchemy/util/compat.py", line 211, in raise_
    raise exception
  File "/home/airflow/.local/lib/python3.7/site-packages/sqlalchemy/pool/impl.py", line 143, in _do_get
    return self._create_connection()
  File "/home/airflow/.local/lib/python3.7/site-packages/sqlalchemy/pool/base.py", line 273, in _create_connection
    return _ConnectionRecord(self)
  File "/home/airflow/.local/lib/python3.7/site-packages/sqlalchemy/pool/base.py", line 388, in __init__
    self.__connect()
  File "/home/airflow/.local/lib/python3.7/site-packages/sqlalchemy/pool/base.py", line 691, in __connect
    pool.logger.debug("Error on connect(): %s", e)
  File "/home/airflow/.local/lib/python3.7/site-packages/sqlalchemy/util/langhelpers.py", line 72, in __exit__
    with_traceback=exc_tb,
  File "/home/airflow/.local/lib/python3.7/site-packages/sqlalchemy/util/compat.py", line 211, in raise_
    raise exception
  File "/home/airflow/.local/lib/python3.7/site-packages/sqlalchemy/pool/base.py", line 686, in __connect
    self.dbapi_connection = connection = pool._invoke_creator(self)
  File "/home/airflow/.local/lib/python3.7/site-packages/sqlalchemy/engine/create.py", line 578, in connect
    return dialect.connect(*cargs, **cparams)
  File "/home/airflow/.local/lib/python3.7/site-packages/sqlalchemy/engine/default.py", line 598, in connect
    return self.dbapi.connect(*cargs, **cparams)
  File "/home/airflow/.local/lib/python3.7/site-packages/psycopg2/__init__.py", line 122, in connect
    conn = _connect(dsn, connection_factory=connection_factory, **kwasync)
sqlalchemy.exc.OperationalError: (psycopg2.OperationalError) could not connect to server: No such file or directory
	Is the server running locally and accepting
	connections on Unix domain socket "/var/run/postgresql/.s.PGSQL.5432"?

(Background on this error at: https://sqlalche.me/e/14/e3q8)
[2023-02-10T13:51:40.118+0000] {taskinstance.py:1323} INFO - Marking task as FAILED. dag_id=cms_asp_noc, task_id=data_load, execution_date=20230210T122258, start_date=20230210T135139, end_date=20230210T135140
[2023-02-10T13:51:40.133+0000] {standard_task_runner.py:105} ERROR - Failed to execute job 1664 for task data_load ((psycopg2.OperationalError) could not connect to server: No such file or directory
	Is the server running locally and accepting
	connections on Unix domain socket "/var/run/postgresql/.s.PGSQL.5432"?

(Background on this error at: https://sqlalche.me/e/14/e3q8); 37342)
[2023-02-10T13:51:40.205+0000] {local_task_job.py:208} INFO - Task exited with return code 1
[2023-02-10T13:51:40.229+0000] {taskinstance.py:2578} INFO - 0 downstream tasks scheduled from follow-on schedule check
