[2023-02-10T12:19:04.639+0000] {taskinstance.py:1083} INFO - Dependencies all met for <TaskInstance: cms_asp_noc.load_test scheduled__2022-05-05T00:00:00+00:00 [queued]>
[2023-02-10T12:19:04.720+0000] {taskinstance.py:1083} INFO - Dependencies all met for <TaskInstance: cms_asp_noc.load_test scheduled__2022-05-05T00:00:00+00:00 [queued]>
[2023-02-10T12:19:04.726+0000] {taskinstance.py:1279} INFO - 
--------------------------------------------------------------------------------
[2023-02-10T12:19:04.732+0000] {taskinstance.py:1280} INFO - Starting attempt 1 of 1
[2023-02-10T12:19:04.742+0000] {taskinstance.py:1281} INFO - 
--------------------------------------------------------------------------------
[2023-02-10T12:19:04.912+0000] {taskinstance.py:1300} INFO - Executing <Task(PythonOperator): load_test> on 2022-05-05 00:00:00+00:00
[2023-02-10T12:19:05.035+0000] {standard_task_runner.py:55} INFO - Started process 32425 to run task
[2023-02-10T12:19:05.275+0000] {standard_task_runner.py:82} INFO - Running: ['***', 'tasks', 'run', 'cms_asp_noc', 'load_test', 'scheduled__2022-05-05T00:00:00+00:00', '--job-id', '1637', '--raw', '--subdir', 'DAGS_FOLDER/cms_upd.py', '--cfg-path', '/tmp/tmpkkgb5a6e']
[2023-02-10T12:19:05.318+0000] {standard_task_runner.py:83} INFO - Job 1637: Subtask load_test
[2023-02-10T12:19:06.880+0000] {task_command.py:388} INFO - Running <TaskInstance: cms_asp_noc.load_test scheduled__2022-05-05T00:00:00+00:00 [running]> on host 2886274f27ea
[2023-02-10T12:19:08.361+0000] {taskinstance.py:1509} INFO - Exporting the following env vars:
AIRFLOW_CTX_DAG_OWNER=***
AIRFLOW_CTX_DAG_ID=cms_asp_noc
AIRFLOW_CTX_TASK_ID=load_test
AIRFLOW_CTX_EXECUTION_DATE=2022-05-05T00:00:00+00:00
AIRFLOW_CTX_TRY_NUMBER=1
AIRFLOW_CTX_DAG_RUN_ID=scheduled__2022-05-05T00:00:00+00:00
[2023-02-10T12:19:08.884+0000] {taskinstance.py:1768} ERROR - Task failed with exception
Traceback (most recent call last):
  File "/home/airflow/.local/lib/python3.7/site-packages/airflow/operators/python.py", line 175, in execute
    return_value = self.execute_callable()
  File "/home/airflow/.local/lib/python3.7/site-packages/airflow/operators/python.py", line 192, in execute_callable
    return self.python_callable(*self.op_args, **self.op_kwargs)
  File "/opt/airflow/dags/cms_pg/load_test.py", line 19, in load_test
    cur.execute("select * from student")
psycopg2.errors.UndefinedTable: relation "student" does not exist
LINE 1: select * from student
                      ^

[2023-02-10T12:19:33.374+0000] {taskinstance.py:1323} INFO - Marking task as FAILED. dag_id=cms_asp_noc, task_id=load_test, execution_date=20220505T000000, start_date=20230210T121904, end_date=20230210T121933
[2023-02-10T12:19:33.928+0000] {standard_task_runner.py:105} ERROR - Failed to execute job 1637 for task load_test (relation "student" does not exist
LINE 1: select * from student
                      ^
; 32425)
[2023-02-10T12:19:36.348+0000] {local_task_job.py:208} INFO - Task exited with return code 1
[2023-02-10T12:19:36.577+0000] {taskinstance.py:2578} INFO - 0 downstream tasks scheduled from follow-on schedule check
